Workbook

Sheet BELUM ADA DI REPORT
A1: SEVFJK25040002 == sudah di input .. Di report masuk bulan Mei..di gsoft bulan april

Sheet SUMMARY 2026
B3: PT. INTEGRA SINERGI LOGITAMA INDONESIA
B4: WEEKLY REPORT
B5: TAHUN | C5: : 2026
B8: BULAN | C8: DIVISI | D8: SELLING | E8: COST | F8: GP
B11: APR | C11: EXPORT
C12: IMPORT | D12: =EXIM!O13 -> 20000000 | E12: =EXIM!P13 -> 10000000 | F12: =EXIM!Q13 -> 10000000
C13: DOMESTIC | D13: =DOM!O24 -> 280500000 | E13: =DOM!P24 -> 242750000 | F13: =D13-E13 -> 37750000 | G13: TOTAL APRIL | H13: =SUM(D11:D13) -> 300500000 | I13: =SUM(E11:E13) -> 252750000 | J13: =SUM(F12:F13) -> 47750000
B15: MAY | C15: EXPORT | D15: =EXIM!O34 -> 135000000 | E15: =EXIM!P34 -> 105000000 | F15: =D15-E15 -> 30000000
C16: IMPORT | D16: =EXIM!O27 -> 89405167 | E16: =EXIM!P27 -> 71905167 | F16: =EXIM!Q27 -> 17500000
C17: DOMESTIC | D17: =DOM!O51 -> 629700000 | E17: =DOM!P51 -> 557900000 | F17: =D17-E17 -> 71800000 | G17: TOTAL MAY | H17: =SUM(D15:D17) -> 854105167 | I17: =SUM(E15:E17) -> 734805167 | J17: =SUM(F15:F17) -> 119300000
B19: JUNE | C19: EXPORT | D19: =EXIM!O50 -> 134662526 | E19: =EXIM!P50 -> 111162526 | F19: =EXIM!Q39 -> 1000000
C20: IMPORT
C21: DOMESTIC | D21: =DOM!O74 -> 481060000 | E21: =DOM!P74 -> 424360000 | F21: =DOM!Q74 -> 56700000 | G21: TOTAL JUNE | H21: =SUM(D19:D21) -> 615722526 | I21: =SUM(E19:E21) -> 535522526 | J21: =SUM(F19:F21) -> 57700000
B23: JULY | C23: EXPORT | D23: =EXIM!O59 -> 32000000 | E23: =EXIM!P59 -> 28000000 | F23: =EXIM!Q59 -> 4000000
C24: IMPORT
C25: DOMESTIC | D25: =DOM!O91 -> 261100000 | E25: =DOM!P91 -> 232200000 | F25: =D25-E25 -> 28900000 | G25: TOTAL JULY | H25: =SUM(D23:D25) -> 293100000 | I25: =SUM(E23:E25) -> 260200000 | J25: =SUM(F23:F25) -> 32900000
B27: AUG | C27: EXPORT
C28: IMPORT
C29: DOMESTIC
B31: SEPT | C31: EXPORT
C32: IMPORT
C33: DOMESTIC
C37: TOTAL (IDR) | D37: =SUM(D11:D36) -> 2063427693 | E37: =SUM(E11:E36) -> 1783277693 | F37: =SUM(F11:F35) -> 257650000 | H37: =SUM(H11:H34) -> 2063427693 | I37: =SUM(I10:I36) -> 1783277693 | J37: =SUM(J11:J35) -> 257650000

Sheet EXIM
B4: PT. INTEGRA SINERGI LOGITAMA INDONESIA
B5: WEEKLY REPORT
B6: TAHUN | C6: : 2026
B8: EXPORT & IMPORT
B9: NO | C9: STFG DATE | D9: NO JOB | E9: SALES | F9: TYPE SHIPMENT | H9: CUSTOMER | I9: POL | J9: POD | K9: QTY CTR | L9: SHIP LINE | M9: VESSEL | N9: ETD | O9: SELLING | P9: COST | Q9: GP
F10: SEA | G10: OTHERS | S10: TGL CETAK INVOICE | T10: TGL PENGIRIMAN INVOICE | U10: TOP | V10: TGL JATUH TEMPO | W10: TGL PEMBAYARAN | X10: PEMBAYARAN | Y10: USIA JATUH TEMPO
B11: APRIL
B12: IMPORT | D12: ISLI-26.04-001 (IMP) | F12: LCL | H12: BUSU PRIMA INTERNUSA | O12: 20000000 | P12: 10000000 | Q12: =O12-P12 -> 10000000 | R12: FINAL
N13: TOTAL IMP APRIL | O13: =O12 -> 20000000 | P13: =P12 -> 10000000 | Q13: =Q12 -> 10000000
B16: MEI
B17: IMPORT | D17: ISLI-26.04-002 (IMP) | F17: LCL | H17: RATINDO | I17: SHANGHAI | J17: JAKARTA | K17: LCL | N17: 46136 | O17: 15200000 | P17: 7600000 | Q17: =O17-P17 -> 7600000 | R17: FINAL | S17: 46161 | T17: 46162 | U17: 14 | V17: =T17+U17 -> 46176 | W17: 46203
N18: REIMBURSE | O18: 646575 | P18: 646575 | Q18: =O18-P18 -> 0
D20: ISLI-26.04-003 (IMP) | F20: FCL | H20: RATINDO | I20: SHANGHAI | J20: JAKARTA | K20: FCL (CIF) | M20: HOCHIMINH V.2604S | N20: 46136 | O20: 11900000 | P20: 8500000 | Q20: =O20-P20 -> 3400000 | R20: FINAL | S20: 46161 | T20: 46162 | U20: 14 | V20: =T20+U20 -> 46176 | W20: 46203
N21: REIMBURSE | O21: 1701630 | P21: 1701630
N22: REIMBURSE | O22: 821400 | P22: 821400
D24: ISLI-26.05-001 (IMP) | F24: FCL | H24: RATINDO | I24: QD | J24: JAKARTA | K24: FCL | N24: 46146 | O24: 37300000 | P24: 30800000 | Q24: =O24-P24 -> 6500000 | R24: FINAL
N25: REIMBURSE | O25: 21835562 | P25: 21835562
N27: TOTAL IMP MEI | O27: =SUM(O17:O26) -> 89405167 | P27: =SUM(P17:P26) -> 71905167 | Q27: =SUM(Q17:Q26) -> 17500000
B31: EXPORT | C31: 1 | D31: ISLI-26.05-001 (EXP) | G31: AIRFREIGHT | H31: DIAMETRAL | I31: JKT | J31: MANILA | K31: LCL (AIRFREIGHT) | L31: SCANSHIPPPING | M31: CEBU PACIFIC 5J-760 | N31: 46144 | O31: 70000000 | P31: 60000000 | Q31: =O31-P31 -> 10000000 | R31: FINAL | S31: 46150 | T31: 46150 | U31: 14 | V31: =U31+T31 -> 46164 | W31: 46167
C32: 2 | D32: ISLI-26.05-002 (EXP) | G32: AIRFREIGHT | H32: DIAMETRAL | I32: JKT | J32: MANILA | K32: LCL (AIRFREIGHT) | L32: SCANSHIPPPING | N32: 46151 | O32: 65000000 | P32: 45000000 | Q32: =O32-P32 -> 20000000 | R32: FINAL | S32: 46161 | T32: 46162 | U32: 14 | V32: =T32+U32 -> 46176 | W32: 46184
N34: TOTAL EXP MEI | O34: =SUM(O31:O33) -> 135000000 | P34: =SUM(P31:P33) -> 105000000 | Q34: =SUM(Q31:Q33) -> 30000000
B38: JUNI
B39: EXPORT | C39: 3 | D39: ISLI-26.06-001 (EXP) | G39: AIRFREIGHT | H39: DIAMETRAL | I39: JKT | J39: MANILA | K39: LCL (AIRFREIGHT) | L39: SCANSHIPPPING | O39: 13000000 | P39: 12000000 | Q39: =O39-P39 -> 1000000 | R39: FINAL | W39: 46184
C40: 4 | D40: ISLI-26.06-002 (EXP) | G40: AIRFREIGHT | H40: DIAMETRAL | I40: JKT | J40: MANILA | K40: LCL (AIRFREIGHT) | L40: SCANSHIPPPING | O40: 50000000 | P40: 45000000 | Q40: =O40-P40 -> 5000000 | R40: FINAL | W40: 46212
D41: ISLI-26.06-003 (EXP) | F41: FCL | H41: DIAMETRAL | I41: JKT | J41: MANILA | K41: 1X20' | L41: ONE | M41: SAINT ANNE | N41: 46180 | O41: 13000000 | P41: 8000000 | Q41: =O41-P41 -> 5000000 | R41: FINAL
D42: ISLI-26.06-004 (EXP) | F42: FCL | H42: DIAMETRAL | I42: JKT | J42: MANILA | K42: 1X20' | L42: CNC | M42: FORT DIAMANT | N42: 46182 | O42: 16000000 | P42: 9500000 | Q42: =O42-P42 -> 6500000 | R42: FINAL
C43: 5 | D43: ISLI-26.06-005 (EXP) | G43: AIRFREIGHT | H43: DIAMETRAL | I43: JKT | J43: MANILA | K43: LCL (AIRFREIGHT) | L43: SCANSHIPPPING | O43: 15000000 | P43: 13000000 | Q43: =O43-P43 -> 2000000 | R43: FINAL | W43: 46212
C44: 6 | D44: ISLI-26.06-006 (EXP) | G44: AIRFREIGHT | H44: DIAMETRAL | I44: JKT | J44: MANILA | K44: LCL (AIRFREIGHT) | L44: SCANSHIPPPING | O44: 12000000 | P44: 10000000 | Q44: =O44-P44 -> 2000000 | R44: FINAL
D45: ISLI-26.06-007 (EXP) | F45: FCL | H45: DIAMETRAL | I45: JKT | J45: MANILA | K45: 1X20' | M45: FORT JAMES | O45: 14000000 | P45: 12000000 | Q45: =O45-P45 -> 2000000 | R45: FINAL
N46: REIMBURSE | O46: 530580 | P46: 530580 | Q46: =O46-P46 -> 0
N47: REIMBURSE | O47: 651946 | P47: 651946 | Q47: =O47-P47 -> 0
N48: REIMBURSE | O48: 480000 | P48: 480000 | Q48: =O48-P48 -> 0
N50: TOTAL EXP JUNI | O50: =SUM(O39:O48) -> 134662526 | P50: =SUM(P39:P48) -> 111162526 | Q50: =SUM(Q39:Q48) -> 23500000
B52: JULI
B53: EXPORT
C54: 7 | D54: ISLI-26.07-001 (EXP) | F54: LCL | H54: DIAMETRAL | I54: JKT | J54: MANILA | K54: LCL (AIRFREIGHT) | L54: SCANSHIPPPING | O54: 14000000 | P54: 12000000 | Q54: =O54-P54 -> 2000000 | R54: FINAL
C55: 8 | D55: ISLI-26.07-002 (EXP) | F55: LCL | H55: DIAMETRAL | I55: JKT | J55: MANILA | K55: LCL (AIRFREIGHT) | L55: SCANSHIPPPING | O55: 18000000 | P55: 16000000 | Q55: =O55-P55 -> 2000000 | R55: FINAL
C56: 9 | D56: ISLI-26.07-003 (EXP) | F56: LCL | H56: DIAMETRAL | I56: JKT | J56: MANILA | K56: LCL (AIRFREIGHT) | L56: SCANSHIPPPING
D57: ISLI-26.07-004 (EXP) | F57: FCL | H57: DIAMETRAL | I57: JKT | J57: MANILA | K57: 1X20' | M57: FORT DIAMANT
N59: TOTAL EXP JULI | O59: =SUM(O54:O56) -> 32000000 | P59: =SUM(P54:P56) -> 28000000 | Q59: =SUM(Q54:Q56) -> 4000000
...

Sheet DOM
B4: PT. INTEGRA SINERGI LOGITAMA INDONESIA
B5: WEEKLY REPORT
B6: TAHUN | C6: : 2026
B8: DOMESTIK
B9: NO | C9: STFG DATE | D9: NO JOB | E9: SALES | F9: TYPE SHIPMENT | H9: CUSTOMER | I9: POL | J9: POD | K9: QTY CTR | L9: SHIP LINE | M9: VESSEL | N9: ETD | O9: SELLING | P9: COST | Q9: GP | R9: PROFIT %
F10: SEA | G10: OTHERS | T10: TGL CETAK INVOICE | U10: TGL PENGIRIMAN INVOICE | V10: TOP | W10: TGL JATUH TEMPO | X10: TGL PEMBAYARAN | Y10: PEMBAYARAN | Z10: KETERANGAN
C11: APRIL
B12: 1 | C12: PAID | D12: ISLI-26.04-001 | E12: KIM | F12: FCL | H12: GLOBAL INDONESIA ASIA SEJAHTERA | I12: JAKARTA | J12: TJ. PINANG | K12: 1X20' | L12: ICON | M12: IC IBRANI XI V.43/26 | N12: 46124 | O12: 14000000 | P12: 12750000 | Q12: =O12-P12 -> 1250000 | R12: =Q12/O12 -> 0.089285714 | S12: FINAL | T12: 46160 | U12: =T12+2 -> 46162 | V12: 30 | W12: =V12+U12 -> 46192 | X12: 46188 | Y12: 29994659 | Z12: OK
B13: 2 | C13: PAID | D13: ISLI-26.04-002 | E13: KIM | F13: FCL | H13: GLOBAL INDONESIA ASIA SEJAHTERA | I13: JAKARTA | J13: TJ. PINANG | K13: 1X20' | L13: ICON | M13: IC IBRANI XI V.43/26 | N13: 46124 | O13: 15000000 | P13: 12700000 | Q13: =O13-P13 -> 2300000 | R13: =Q13/O13 -> 0.15333333 | S13: FINAL | T13: 46160 | U13: =T13+2 -> 46162 | V13: 30 | W13: =V13+U13 -> 46192 | X13: 46188 | Z13: OK
B14: 3 | C14: PAID | D14: ISLI-26.04-003 | E14: KIM | F14: FCL | H14: TOTAL BANGUN PERSADA | I14: JAKARTA | J14: BATAM | K14: 1X20' | L14: MERATUS | M14: MERATUS AMPANA JB464N | N14: 46133 | O14: ='[1]04-003'!$E$16 -> 16500000 | P14: 15000000 | Q14: =O14-P14 -> 1500000 | R14: =Q14/O14 -> 0.090909091 | S14: FINAL | T14: 46177 | U14: =T14+1 -> 46178 | V14: 30 | W14: =(U14+V14)+3 -> 46211 | X14: 46213 | Z14: OK
B15: 4 | C15: PAID | D15: ISLI-26.04-004 | E15: KIM | F15: FCL | H15: SINAR INDAH LOGISTIK | I15: JAKARTA | J15: BANJARMASIN | K15: 1X20' | L15: CTP | M15: INTAN DAYA 4 V. 13N26 | N15: 46132 | O15: 31000000 | P15: 28000000 | Q15: =O15-P15 -> 3000000 | R15: =Q15/O15 -> 0.096774194 | S15: FINAL | T15: 46134 | U15: 46134 | V15: 30 | W15: =U15+V15 -> 46164 | X15: 46198 | Z15: LATE 34 HARI
B16: 5 | D16: ISLI-26.04-005 | E16: KIM | F16: FCL | H16: GLOBAL ANUGRAH LOGISTIK | I16: JAKARTA | J16: BANJARMASIN | K16: 1X20' | L16: CTP | M16: INTAN DAYA 4 V. 13N26 | N16: 46132 | O16: ='[1]04-005'!$E$16 -> 17500000 | P16: 15000000 | Q16: =O16-P16 -> 2500000 | R16: =Q16/O16 -> 0.14285714 | S16: FINAL | T16: 46184 | U16: =T16+1 -> 46185 | V16: 30 | W16: =(U16+V16)+3 -> 46218
B17: 6 | C17: PAID | D17: ISLI-26.04-006 | E17: KIM | F17: FCL | H17: GLOBAL INDONESIA ASIA SEJAHTERA | I17: PERAWANG | J17: SURABAYA | K17: 1X20' | L17: PULAU LAUT | M17: WGM 0285S | N17: 46136 | O17: 36000000 | P17: 33000000 | Q17: =O17-P17 -> 3000000 | R17: =Q17/O17 -> 0.083333333 | S17: FINAL | T17: 46161 | U17: =T17+2 -> 46163 | V17: 30 | W17: =V17+U17 -> 46193 | X17: 46196 | Z17: LATE 3 HARI
B18: 7 | C18: PAID | D18: ISLI-26.04-007 | E18: KIM | F18: FCL | H18: GLOBAL INDONESIA ASIA SEJAHTERA | I18: JAKARTA | J18: PONTIANAK | K18: 1X20' | L18: SINDO | M18: LL 2528 V. 31 JN // Dody | N18: 46133 | O18: 15000000 | P18: 11200000 | Q18: =O18-P18 -> 3800000 | R18: =Q18/O18 -> 0.25333333 | S18: FINAL | T18: 46154 | U18: =T18+1 -> 46155 | V18: 30 | W18: =V18+U18 -> 46185 | X18: 46196 | Z18: LATE 11 HARI
B19: 8 | C19: PAID | D19: ISLI-26.04-008 | E19: KIM | F19: FCL | H19: GLOBAL INDONESIA ASIA SEJAHTERA | I19: JAKARTA | J19: PONTIANAK | K19: 3X20' | L19: SINDO | M19: LL 2528 V. 31 JN // Dody | N19: 46133 | O19: 49000000 | P19: 37000000 | Q19: =O19-P19 -> 12000000 | R19: =Q19/O19 -> 0.24489796 | S19: FINAL | T19: 46154 | U19: =T19+1 -> 46155 | V19: 30 | W19: =V19+U19 -> 46185 | X19: 46188 | Y19: 48520772 | Z19: OK
B20: 9 | C20: PAID | D20: ISLI-26.04-009 | E20: KIM | F20: FCL | H20: GLOBAL ANUGRAH LOGISTIK | I20: JAKARTA | J20: BELAWAN | K20: 1X20' | L20: TEMAS | M20: IZUMI MAS V.2226 | N20: 46137 | O20: ='[1]04-009'!$E$16 -> 29300000 | P20: 26500000 | Q20: =O20-P20 -> 2800000 | R20: =Q20/O20 -> 0.09556314 | S20: FINAL | T20: 46161 | U20: =T20+2 -> 46163 | V20: 30 | W20: =V20+U20 -> 46193 | X20: 46203 | Z20: LATE 10 HARI
B21: 10 | C21: PAID | D21: ISLI-26.04-010 | E21: KIM | F21: FCL | H21: GLOBAL INDONESIA ASIA SEJAHTERA | I21: PERAWANG | J21: SURABAYA | K21: 1X40' | L21: LKA | M21: LINTAS 18 V.06/26 | N21: 46130 | O21: 36000000 | P21: 33100000 | Q21: =O21-P21 -> 2900000 | R21: =Q21/O21 -> 0.080555556 | S21: FINAL | T21: 46161 | U21: =T21+2 -> 46163 | V21: 30 | W21: =V21+U21 -> 46193 | X21: 46196 | Z21: LATE 3 HARI
B22: 11 | C22: PAID | D22: ISLI-26.04-011 | E22: KIM | F22: FCL | H22: DAVINDO | I22: JAKARTA | J22: PONTIANAK | K22: 1X20' | L22: LKA | O22: ='[1]04-011'!$E$16 -> 21200000 | P22: 18500000 | Q22: =O22-P22 -> 2700000 | R22: =Q22/O22 -> 0.12735849 | S22: FINAL | T22: 46153 | U22: 46154 | V22: 30 | W22: =V22+U22 -> 46184 | X22: 46185 | Y22: 21200000 | Z22: OK
N24: TOTAL APRIL | O24: =SUM(O12:O22) -> 280500000 | P24: =SUM(P12:P23) -> 242750000 | Q24: =SUM(Q12:Q23) -> 37750000
C25: MEI
B26: 1 | D26: ISLI-26.05-001 | E26: KIM | F26: FCL | H26: GLOBAL ANUGRAH LOGISTIK | I26: JAKARTA | J26: ACEH | K26: 1X20' | L26: TEMAS | M26: LAGUN MAS | N26: 38843 | O26: 20000000 | P26: 18000000 | Q26: =O26-P26 -> 2000000 | R26: =Q26/O26 -> 0.1 | S26: FINAL | T26: 46177 | U26: =T26+1 -> 46178 | V26: 30 | W26: =(U26+V26)+3 -> 46211
B27: 2 | C27: PAID | D27: ISLI-26.05-002 | E27: KIM | F27: FCL | H27: TOTAL BANGUN PERSADA | I27: JAKARTA | J27: BATAM | K27: 1X20' | L27: ICON | M27: ICON IBRANI XI V.52/26 | N27: 38840 | O27: ='[2]05-002'!$E$16 -> 16500000 | P27: 14000000 | Q27: =O27-P27 -> 2500000 | R27: =Q27/O27 -> 0.15151515 | S27: FINAL | T27: 46177 | U27: =T27+1 -> 46178 | V27: 30 | W27: =(U27+V27)+3 -> 46211 | X27: 46213 | Z27: OK
B28: 3 | D28: ISLI-26.05-003 | E28: KIM | F28: FCL | H28: GLOBAL INDONESIA ASIA SEJAHTERA | I28: PERAWANG | J28: BITUNG | K28: 1X40' | L28: SPIL | M28: SELILI BARU | N28: 46146 | O28: 38000000 | P28: 33000000 | Q28: =O28-P28 -> 5000000 | R28: =Q28/O28 -> 0.13157895 | S28: FINAL | T28: 46206
B29: 4 | C29: PAID | D29: ISLI-26.05-004 | E29: KIM | F29: FCL | H29: DAVINDO | I29: JAKARTA | J29: BANJARMASIN | K29: 2X20' | L29: CTP | M29: INTAN DAYA 4 | N29: 46147 | O29: ='[2]05-004'!$G$16 -> 41000000 | P29: 36000000 | Q29: =O29-P29 -> 5000000 | R29: =Q29/O29 -> 0.12195122 | S29: FINAL | T29: 46168 | U29: 46168 | V29: 30 | W29: =U29+V29 -> 46198 | X29: 46206 | Z29: LATE 6 HARI
B30: 5 | D30: ISLI-26.05-005 | E30: KIM | F30: FCL | H30: MATEREE NUSANTARA | I30: JAKARTA | J30: PALU | K30: 1X21' | L30: MERATUS | M30: MERATUS KONAWE BS425N | N30: 46149 | O30: ='[2]05-005'!$E$16 -> 24300000 | P30: 22000000 | Q30: =O30-P30 -> 2300000 | R30: =Q30/O30 -> 0.094650206 | S30: FINAL | T30: 46206
B31: 6 | D31: ISLI-26.05-006 | E31: KIM | F31: FCL | H31: TOTAL BANGUN PERSADA | I31: JAKARTA | J31: BATAM | K31: 2X20' | L31: ICON | M31: IC IBRANI XI V.54 | N31: 46153 | O31: ='[2]05-006'!$G$16 -> 33000000 | P31: 29500000 | Q31: =O31-P31 -> 3500000 | R31: =Q31/O31 -> 0.10606061 | S31: FINAL | T31: 46184 | U31: =T31+1 -> 46185 | V31: 30 | W31: =(U31+V31)+3 -> 46218
B32: 7 | D32: ISLI-26.05-007 | E32: KIM | F32: FCL | H32: GLOBAL INDONESIA ASIA SEJAHTERA | I32: PERAWANG | J32: PALU | K32: 1X40' | L32: SPIL | M32: PULAU LAYANG V.10 | N32: 46154 | O32: 36000000 | P32: 33000000 | Q32: =O32-P32 -> 3000000 | R32: =Q32/O32 -> 0.083333333 | S32: FINAL | T32: 46206
B33: 8 | D33: ISLI-26.05-008 | E33: KIM | F33: FCL | H33: TOTAL BANGUN PERSADA | I33: JAKARTA | J33: BATAM | K33: 3X20' | L33: MERATUS | M33: MERATUS AMURANG VJB467N | N33: 46160 | O33: ='[2]05-008'!$F$16 -> 49500000 | P33: 44000000 | Q33: =O33-P33 -> 5500000 | R33: =Q33/O33 -> 0.11111111 | S33: FINAL | T33: 46190 | U33: =T33+1 -> 46191 | V33: 30 | W33: 46224
B34: 9 | D34: ISLI-26.05-009 | E34: KIM | F34: FCL | H34: GLOBAL INDONESIA ASIA SEJAHTERA | I34: PERAWANG | J34: GORONTALO | K34: 1X40' | L34: SPIL | M34: PULAU LAYANG V.10 | N34: 46154 | O34: 41500000 | P34: 39000000 | Q34: =O34-P34 -> 2500000 | R34: =Q34/O34 -> 0.060240964 | S34: FINAL | T34: 46203
B35: 10 | D35: ISLI-26.05-010 | E35: KIM | F35: FCL | H35: GLOBAL ANUGRAH LOGISTIK | I35: JAKARTA | J35: MEDAN | K35: 1X20' | L35: CTP | M35: INTAN DAYA 298 V.12N26 | N35: 46161 | O35: ='[2]05-010'!$E$16 -> 29300000 | P35: 25600000 | Q35: =O35-P35 -> 3700000 | R35: =Q35/O35 -> 0.12627986 | S35: FINAL | T35: 46184 | U35: =T35+1 -> 46185 | V35: 30 | W35: 46224
B36: 11 | C36: PAID | D36: ISLI-26.05-011 | E36: KIM | F36: FCL | H36: GLOBAL INDONESIA ASIA SEJAHTERA | I36: PERAWANG | J36: JAKARTA | K36: 1X40' | L36: TEMAS | M36: UMBUL MAS V.29 | N36: 46159 | O36: 17800000 | P36: 16000000 | Q36: =O36-P36 -> 1800000 | R36: =Q36/O36 -> 0.1011236 | S36: FINAL | T36: 46177 | U36: =T36+1 -> 46178 | V36: 30 | W36: 46224 | X36: 46209 | Z36: OK
B37: 12 | D37: ISLI-26.05-012 | E37: KIM | F37: FCL | H37: GLOBAL INDONESIA ASIA SEJAHTERA | I37: PERAWANG | J37: SURABAYA | K37: 1X40' | L37: LKA | M37: LINTAS 18 | N37: 46157 | O37: 37000000 | P37: 33300000 | Q37: =O37-P37 -> 3700000 | R37: =Q37/O37 -> 0.1 | S37: FINAL | T37: 46190 | U37: =T37+1 -> 46191 | V37: 30 | W37: 46224
B38: 13 | D38: ISLI-26.05-013 | E38: KIM | F38: FCL | H38: GLOBAL ANUGRAH LOGISTIK | I38: JAKARTA | J38: MEDAN | K38: 1X20' | L38: CTP | M38: INTAN DAYA 298 V.12N26 | N38: 46161 | O38: ='[2]05-013'!$E$16 -> 29300000 | P38: 25800000 | Q38: =O38-P38 -> 3500000 | R38: =Q38/O38 -> 0.11945392 | S38: FINAL | T38: 46184 | U38: =T38+1 -> 46185 | V38: 30 | W38: 46224
B39: 14 | D39: ISLI-26.05-014 | E39: KIM | F39: FCL | H39: GLOBAL INDONESIA ASIA SEJAHTERA | I39: PERAWANG | J39: KENDARI | K39: 1X40' | L39: TEMAS | M39: UMBUL MAS V.29 | N39: 46159 | O39: 39500000 | P39: 35500000 | Q39: =O39-P39 -> 4000000 | R39: =Q39/O39 -> 0.10126582
B40: 15 | D40: ISLI-26.05-015 | E40: KIM | F40: FCL | H40: GLOBAL INDONESIA ASIA SEJAHTERA | I40: PERAWANG | J40: BITUNG | K40: 1X40' | L40: SPIL | M40: SELILI BARU V.10 | N40: 46160 | O40: 37500000 | P40: 31400000 | Q40: =O40-P40 -> 6100000 | R40: =Q40/O40 -> 0.16266667 | S40: FINAL | T40: 46206
B41: 16 | D41: ISLI-26.05-016 | E41: KIM | F41: FCL | H41: GLOBAL INDONESIA ASIA SEJAHTERA | I41: PERAWANG | J41: PALU | K41: 1X40' | L41: SPIL | M41: SELILI BARU V.10 | N41: 46160 | O41: 39800000 | P41: 33200000 | Q41: =O41-P41 -> 6600000 | R41: =Q41/O41 -> 0.16582915 | S41: FINAL | T41: 46206
B42: 17 | D42: ISLI-26.05-017 | E42: KIM | F42: FCL | H42: TANJUNG UNCANG | I42: SURABAYA | J42: BATAM | K42: 1X20' | L42: TEMAS | M42: TELAGA MAS V.43 | N42: 46160 | O42: 21200000 | P42: 19000000 | Q42: =O42-P42 -> 2200000 | R42: =Q42/O42 -> 0.10377358 | S42: FINAL | T42: 46190 | U42: =T42+1 -> 46191 | V42: 30 | W42: 46224
B43: 18 | D43: ISLI-26.05-018 | E43: KIM | F43: FCL | H43: GLOBAL INDONESIA ASIA SEJAHTERA | I43: PERAWANG | J43: SURABAYA | K43: 1X40' | L43: LKA | M43: LINTAS MAHAKAM V.10 | O43: 37500000 | P43: 33500000 | Q43: =O43-P43 -> 4000000 | R43: =Q43/O43 -> 0.10666667 | S43: FINAL | T43: 46190 | U43: =T43+1 -> 46191 | V43: 30 | W43: 46224
B44: 19 | C44: PAID | D44: ISLI-26.05-019 | E44: KIM | F44: FCL | H44: GLOBAL INDONESIA ASIA SEJAHTERA | I44: PERAWANG | J44: JAKARTA | K44: 1X40' | L44: TEMAS | M44: HILIR MAS | O44: 17000000 | P44: 15400000 | Q44: =O44-P44 -> 1600000 | R44: =Q44/O44 -> 0.094117647 | S44: FINAL | T44: 46177 | U44: =T44+1 -> 46178 | V44: 30 | W44: 46224 | X44: 46209
B45: 20 | D45: ISLI-26.05-020 | E45: KIM | F45: FCL | H45: MATEREE NUSANTARA | I45: JAKARTA | J45: BITUNG | K45: 1X20' | L45: SPIL | M45: ORIENTAL EMERALD | N45: 46164 | O45: ='[2]05-020'!$E$16 -> 24000000 | P45: 20700000 | Q45: =O45-P45 -> 3300000 | R45: =Q45/O45 -> 0.1375 | S45: FINAL | T45: 46196 | U45: 46197 | V45: 30 | W45: =U45+V45+3 -> 46230
...

Sheet Sheet1
B3: PEMBAYARAN PELAYARAN
B5: SPIL
B6: SELILI BARU | C6: PRW-PALU | D6: 05-016 | E6: 22560000
B7: PULAU LAYANG | C7: PRW-PALU | D7: 05-007 | E7: 22560000
B9: TEMAS
B10: UMBUL MAS | C10: PRW-KDI | D10: 05-014 | E10: 26220000
D12: TOTAL | E12: =SUM(E6:E11) -> 71340000
B15: DROPPING | C15: 200000000 | D15: DARI PAK TEGUH
B17: PEMAKAIAN
B18: PENGEMBALIAN KE RATINDO | C18: 70000000
B19: PEMBAYARAN KM LINTAS MAHAKAM | C19: 17060000 | D19: PELAYARAN
B20: PEMBAYARAN KM SELILI BARU | C20: 20723000 | D20: PELAYARAN
B21: PEMBAYARAN KM ORIENTAL EMERALD | C21: 11210000 | D21: PELAYARAN
C22: 1200465 | D22: BONGKAR MUAT
B23: PEMBAYARAN KM PULAU LAYANG | C23: 29015000 | D23: PELAYARAN
B24: PEMBAYARAN CICILAN MOBIL | C24: 6000000
B25: PETTY CASH | C25: 5000000
B26: PEMBAYARAN KE GFLINE | C26: 12904910 | D26: AGENT DOORING
B27: PEMBAYARAN DEA NATASIA | C27: 9906036 | D27: AGENT DOORING
B28: PEMBAYARAN KE META LINTAS | C28: 27100000 | D28: AGENT DOORING
B30: TOTAL PEMBAYARAN | C30: =SUM(C18:C29) -> 210119411
